Workbook
Name Bulan_Code: #REF!
Name Entitas_Code: #REF!
Name FOTO: INDEX([1]Bantu!$E$16:$E$19,MATCH('[1]Pivot Table'!$B$6,[1]Bantu!$D$16:$D$19,0))
Name OpCa: #REF!
Name SBU: #REF!
Name SBU_code: #REF!
Name status_budget: #REF!
Name status_unbudgeted: #REF!

Sheet WBS
B3: WBS Element | C3: Description
B4: AB3.11-06.02.09.01 | C4: PPIC/Divisi/Training
B5: AB3.11-06.02.09.02 | C5: PPIC/Divisi/Perjalanan Dinas
B6: AB3.11-06.02.09.04 | C6: PPIC/Divisi/Operational Expense
B7: AB3.11-06.02.10.01 | C7: HRGS Site/Divisi/Training
B8: AB3.11-06.02.10.02 | C8: HRGS Site/Divisi/Perjalanan Dinas
B9: AB3.11-06.02.10.04 | C9: HRGS Site/Divisi/Operational Expense
B10: AB3.11-06.02.11.01 | C10: Operation/Divisi/Training
B11: AB3.11-06.02.11.02 | C11: Operation/Divisi/Perjalanan Dinas
B12: AB3.11-06.02.11.03 | C12: Operation/Divisi/Konsultan/Eksternal
B13: AB3.11-06.02.11.04 | C13: Operation/Divisi/Operational Expense
B14: AB3.11-06.02.11.05 | C14: Operation/Divisi/Perizinan
... B28: AB3.11-06.02.22.04 | C28: Revegetasi R&R/Divisi/Operational Expens

Sheet HCGA Okt 2026
D2: PT ENERGI BATUBARA LESTARI RENCANA ANGGARAN BULANAN (RAB) Departemen HCGA
B5: Hasnur Group
B7: Lokasi | E7: : Site EBL - RANTAU | G7: Periode | J7: Halaman : 1/1
G8: Bulan : Oktober Tahun : 2026
N9: jika total nilai >25jt (Approval s/d Pak Rahmad)
B10: Kepada | D10: Finance HO | N10: Disetujui Oleh,
B11: Up. | N11: Operation & HCA Director
B12: No. RAB
B14: Tanggal | N14: Rahmad Pudjotomo
N15: Tanggal :
B17: NO. | C17: Kode WBS / Cost Center | D17: Desc. WBS | E17: Uraian | F17: Minggu I | G17: Minggu II | H17: Minggu III | I17: Minggu IV | J17: Total
B19: 1 | D19: =VLOOKUP(C19,WBS!$B:$C,2,0) -> #N/A | E19: Keperluan ATK | F19: =ATK!H20 -> 0 | G19: =ATK!H35 -> 0 | H19: =ATK!H50 -> 0 | I19: =ATK!H65 -> 0 | J19: =SUM(F19:I19) -> 0
B20: =1+B19 -> 2 | E20: Keperluan BBM | F20: =BBM!H20 -> 0 | G20: =BBM!H35 -> 0 | H20: =BBM!H50 -> 0 | I20: =BBM!H65 -> 0 | J20: =SUM(F20:I20) -> 0
B21: =1+B20 -> 3 | E21: Kebutuhan Catering | F21: =Catering!H20 -> 0 | G21: =BBM!H36 -> 0 | H21: =Catering!H52 -> 0 | I21: =Catering!H67 -> 0 | J21: =SUM(F21:I21) -> 0
B22: =1+B21 -> 4 | E22: Perdin & Cuti Karyawan | F22: ='Perdin & Cuti'!H20 -> 0 | G22: ='Perdin & Cuti'!H35 -> 0 | H22: ='Perdin & Cuti'!H50 -> 0 | I22: ='Perdin & Cuti'!H65 -> 0 | J22: =SUM(F22:I22) -> 0
B23: =1+B22 -> 5 | E23: Keperluan Listrik PLN | F23: ='Listrik PLN'!H15 -> 0 | G23: ='Listrik PLN'!H25 -> 0 | H23: ='Listrik PLN'!H35 -> 0 | I23: ='Listrik PLN'!H45 -> 0 | J23: =SUM(F23:I23) -> 0
B24: =1+B23 -> 6 | E24: Keperluan Air PDAM | F24: ='Air PDAM'!H16 -> 0 | G24: ='Air PDAM'!H26 -> 0 | H24: ='Air PDAM'!H36 -> 0 | I24: ='Air PDAM'!H46 -> 0 | J24: =SUM(F24:I24) -> 0
B25: =1+B24 -> 7 | E25: Keperluan Telp & Internet | F25: ='Telp & Internet'!H17 -> 0 | G25: ='Telp & Internet'!H27 -> 0 | H25: ='Telp & Internet'!H37 -> 0 | I25: ='Telp & Internet'!H47 -> 0 | J25: =SUM(F25:I25) -> 0
B26: =1+B25 -> 8 | E26: Keperluan Pantry | F26: =Pantry!H21 -> 0 | G26: =Pantry!H37 -> 0 | H26: =Pantry!H53 -> 0 | I26: =Pantry!H69 -> 0 | J26: =SUM(F26:I26) -> 0
B27: =1+B26 -> 9 | E27: Keperluan Upah KHL | F27: =KHL!H20 -> 0 | G27: =KHL!H35 -> 0 | H27: =KHL!H50 -> 0 | I27: =KHL!H65 -> 0 | J27: =SUM(F27:I27) -> 0
B28: =1+B27 -> 10 | E28: Keperluan Pengajian | J28: =SUM(F28:I28) -> 0
B29: =1+B28 -> 11 | J29: =SUM(F29:I29) -> 0
B30: =1+B29 -> 12 | E30: Keperluan …..... | J30: =SUM(F30:I30) -> 0
B31: =1+B30 -> 13 | E31: Keperluan …..... | J31: =SUM(F31:I31) -> 0
B32: =1+B31 -> 14 | E32: Keperluan …..... | J32: =SUM(F32:I32) -> 0
B33: Total | F33: =SUM(F19:F28) -> 0 | G33: =SUM(G19:G28) -> 0 | H33: =SUM(H19:H28) -> 0 | I33: =SUM(I19:I28) -> 0 | J33: =SUM(J19:J28) -> 0

Sheet ATK
C2: PT ENERGI BATUBARA LESTARI RENCANA ANGGARAN BULANAN (RAB) Departemen HCGA
C7: Keperluan ATK W1 Oktober 2026
C8: No | D8: Nama Barang/Jasa | E8: Qty | F8: Satuan | G8: Harga Satuan | H8: Total Harga
C10: 1 | F10: Pack | H10: =G10*E10 -> 0
C11: =1+C10 -> 2 | H11: =G11*E11 -> 0
C12: =1+C11 -> 3 | H12: =G12*E12 -> 0
C13: =1+C12 -> 4 | H13: =G13*E13 -> 0
C14: =1+C13 -> 5 | H14: =G14*E14 -> 0
C15: =1+C14 -> 6 | H15: =G15*E15 -> 0
C16: =1+C15 -> 7 | H16: =G16*E16 -> 0
C17: =1+C16 -> 8 | H17: =G17*E17 -> 0
C18: =1+C17 -> 9 | H18: =G18*E18 -> 0
C19: =1+C18 -> 10 | H19: =G19*E19 -> 0
C20: Total | H20: =SUM(H10:H19) -> 0 | I20: =H20 -> 0
C22: Keperluan ATK W2 Oktober 2026
C23: No | D23: Nama Barang/Jasa | E23: Qty | F23: Satuan | G23: Harga Satuan | H23: Total Harga
C25: 1 | H25: =G25*E25 -> 0
C26: =1+C25 -> 2 | H26: =G26*E26 -> 0
C27: =1+C26 -> 3 | H27: =G27*E27 -> 0
C28: =1+C27 -> 4 | H28: =G28*E28 -> 0
C29: =1+C28 -> 5 | H29: =G29*E29 -> 0
C30: =1+C29 -> 6 | H30: =G30*E30 -> 0
C31: =1+C30 -> 7 | H31: =G31*E31 -> 0
C32: =1+C31 -> 8 | H32: =G32*E32 -> 0
C33: =1+C32 -> 9 | H33: =G33*E33 -> 0
C34: =1+C33 -> 10 | H34: =G34*E34 -> 0
C35: Total | H35: =SUM(H25:H34) -> 0 | I35: =H35 -> 0
C37: Keperluan ATK W3 Oktober 2026
C38: No | D38: Nama Barang/Jasa | E38: Qty | F38: Satuan | G38: Harga Satuan | H38: Total Harga
C40: 1 | H40: =G40*E40 -> 0
C41: =1+C40 -> 2 | H41: =G41*E41 -> 0
C42: =1+C41 -> 3 | H42: =G42*E42 -> 0
C43: =1+C42 -> 4 | H43: =G43*E43 -> 0
C44: =1+C43 -> 5 | H44: =G44*E44 -> 0
C45: =1+C44 -> 6 | H45: =G45*E45 -> 0
C46: =1+C45 -> 7 | H46: =G46*E46 -> 0
C47: =1+C46 -> 8 | H47: =G47*E47 -> 0
C48: =1+C47 -> 9 | H48: =G48*E48 -> 0
C49: =1+C48 -> 10 | H49: =G49*E49 -> 0
C50: Total | H50: =SUM(H40:H49) -> 0 | I50: =H50 -> 0
...

Sheet BBM
C2: PT ENERGI BATUBARA LESTARI RENCANA ANGGARAN BULANAN (RAB) Departemen HCGA
C7: Keperluan BBM W1 Oktober 2026
C8: No | D8: Nama Barang/Jasa | E8: Qty | F8: Satuan | G8: Harga Satuan | H8: Total Harga
C10: 1 | D10: BBM Honda CRF BG 2053 BBF | H10: =G10*E10 -> 0
C11: =1+C10 -> 2 | D11: BBM Toyota Hilux Vendor Bobby 1 | H11: =G11*E11 -> 0
C12: =1+C11 -> 3 | D12: BBM Toyota Hilux Vendor Bobby 2 | H12: =G12*E12 -> 0
C13: =1+C12 -> 4 | D13: BBM Toyota Hilux Vendor Bobby 3 | H13: =G13*E13 -> 0
C14: =1+C13 -> 5 | H14: =G14*E14 -> 0
C15: =1+C14 -> 6 | H15: =G15*E15 -> 0
C16: =1+C15 -> 7 | H16: =G16*E16 -> 0
C17: =1+C16 -> 8 | H17: =G17*E17 -> 0
C18: =1+C17 -> 9 | H18: =G18*E18 -> 0
C19: =1+C18 -> 10 | H19: =G19*E19 -> 0
C20: Total | H20: =SUM(H10:H19) -> 0 | I20: =H20 -> 0
C22: Keperluan BBM W2 Oktober 2026
C23: No | D23: Nama Barang/Jasa | E23: Qty | F23: Satuan | G23: Harga Satuan | H23: Total Harga
C25: 1 | D25: BBM Honda CRF BG 2053 BBF | H25: =G25*E25 -> 0
C26: =1+C25 -> 2 | D26: BBM Toyota Hilux Vendor Bobby 1 | H26: =G26*E26 -> 0
C27: =1+C26 -> 3 | D27: BBM Toyota Hilux Vendor Bobby 2 | H27: =G27*E27 -> 0
C28: =1+C27 -> 4 | D28: BBM Toyota Hilux Vendor Bobby 3 | H28: =G28*E28 -> 0
C29: =1+C28 -> 5 | H29: =G29*E29 -> 0
C30: =1+C29 -> 6 | H30: =G30*E30 -> 0
C31: =1+C30 -> 7 | H31: =G31*E31 -> 0
C32: =1+C31 -> 8 | H32: =G32*E32 -> 0
C33: =1+C32 -> 9 | H33: =G33*E33 -> 0
C34: =1+C33 -> 10 | H34: =G34*E34 -> 0
C35: Total | H35: =SUM(H25:H34) -> 0 | I35: =H35 -> 0
C37: Keperluan BBM W3 Oktober 2026
C38: No | D38: Nama Barang/Jasa | E38: Qty | F38: Satuan | G38: Harga Satuan | H38: Total Harga
C40: 1 | D40: BBM Honda CRF BG 2053 BBF | H40: =G40*E40 -> 0
C41: =1+C40 -> 2 | D41: BBM Toyota Hilux Vendor Bobby 1 | H41: =G41*E41 -> 0
C42: =1+C41 -> 3 | D42: BBM Toyota Hilux Vendor Bobby 2 | H42: =G42*E42 -> 0
C43: =1+C42 -> 4 | D43: BBM Toyota Hilux Vendor Bobby 3 | H43: =G43*E43 -> 0
C44: =1+C43 -> 5 | H44: =G44*E44 -> 0
C45: =1+C44 -> 6 | H45: =G45*E45 -> 0
C46: =1+C45 -> 7 | H46: =G46*E46 -> 0
C47: =1+C46 -> 8 | H47: =G47*E47 -> 0
C48: =1+C47 -> 9 | H48: =G48*E48 -> 0
C49: =1+C48 -> 10 | H49: =G49*E49 -> 0
C50: Total | H50: =SUM(H40:H49) -> 0 | I50: =H50 -> 0
...

Sheet Catering
C2: PT ENERGI BATUBARA LESTARI RENCANA ANGGARAN BULANAN (RAB) Departemen HCGA
C7: Keperluan Catering W1 Oktober 2026 | L7: Karyawan | R7: KHL | X7: PPAD
C8: No | D8: Nama Barang/Jasa | E8: Qty | F8: Satuan | G8: Harga Satuan | H8: Total Harga | L8: No | M8: Nama | N8: Jml Hari | O8: Makan/Hari | P8: Per Meal | Q8: Total | R8: No | S8: Nama | T8: Jml Hari | U8: Makan/Hari | V8: Per Meal | W8: Total | X8: No | Y8: Nama | Z8: Jml Hari | AA8: Makan/Hari | AB8: Per Meal | AC8: Total
L9: 1 | M9: Pak Widodo | N9: 7 | O9: 3 | P9: 20000 | Q9: =N9*O9*P9 -> 420000 | R9: 1 | S9: Bu Ijah | T9: 7 | U9: 3 | V9: 20000 | W9: =T9*U9*V9 -> 420000 | AC9: =Z9*AA9*AB9 -> 0
C10: 1 | D10: Catering Staff (7 Orang) | F10: pack | H10: =G10*E10 -> 0 | L10: =+L9+1 -> 2 | M10: Haris | N10: 7 | O10: 3 | P10: 20000 | Q10: =N10*O10*P10 -> 420000 | R10: =1+R9 -> 2 | S10: Bu Suryani | T10: 7 | U10: 1 | V10: 20000 | W10: =T10*U10*V10 -> 140000
C11: =1+C10 -> 2 | D11: Catering KHL (3 Orang) | F11: pack | H11: =G11*E11 -> 0 | L11: =+L10+1 -> 3 | M11: Gautama | N11: 7 | O11: 3 | P11: 20000 | Q11: =N11*O11*P11 -> 420000 | R11: =1+R10 -> 3 | S11: KHL Security Mess | T11: 7 | U11: 1 | V11: 20000 | W11: =T11*U11*V11 -> 140000
C12: =1+C11 -> 3 | H12: =G12*E12 -> 0 | L12: =1+L11 -> 4 | M12: Aceng | N12: 7 | O12: 3 | P12: 20000 | Q12: =N12*O12*P12 -> 420000
C13: =1+C12 -> 4 | H13: =G13*E13 -> 0 | L13: =1+L12 -> 5 | M13: Dimas | N13: 7 | O13: 3 | P13: 20000 | Q13: =N13*O13*P13 -> 420000
C14: =1+C13 -> 5 | H14: =G14*E14 -> 0 | L14: =1+L13 -> 6 | M14: Heri Setiawan | N14: 7 | O14: 3 | P14: 20000 | Q14: =N14*O14*P14 -> 420000
C15: =1+C14 -> 6 | H15: =G15*E15 -> 0 | L15: =1+L14 -> 7 | M15: Pengganti SHE | N15: 7 | O15: 3 | P15: 20000 | Q15: =N15*O15*P15 -> 420000
C16: =1+C15 -> 7 | H16: =G16*E16 -> 0 | Q16: =N16*O16*P16 -> 0
C17: =1+C16 -> 8 | H17: =G17*E17 -> 0 | Q17: =N17*O17*P17 -> 0
C18: =1+C17 -> 9 | H18: =G18*E18 -> 0 | Q18: =N18*O18*P18 -> 0
C19: =1+C18 -> 10 | H19: =G19*E19 -> 0 | Q19: =N19*O19*P19 -> 0
C20: Total | H20: =SUM(H10:H19) -> 0 | I20: =H20 -> 0 | Q20: =N20*O20*P20 -> 0
Q21: =N21*O21*P21 -> 0
C22: Keperluan Catering W2 Oktober 2026 | Q22: =N22*O22*P22 -> 0
C23: No | D23: Nama Barang/Jasa | E23: Qty | F23: Satuan | G23: Harga Satuan | H23: Total Harga | Q23: =N23*O23*P23 -> 0
Q24: =N24*O24*P24 -> 0
Q25: =N25*O25*P25 -> 0
C26: 1 | D26: Catering Staff (7 Orang) | F26: pack | H26: =G26*E26 -> 0 | J26: =E26/15 -> 0 | Q26: =N26*O26*P26 -> 0
C27: =1+C25 -> 1 | D27: Catering KHL (3 Orang) | F27: pack | H27: =G27*E27 -> 0 | Q27: =N27*O27*P27 -> 0
C28: =1+C27 -> 2 | H28: =G28*E28 -> 0 | L28: Total | Q28: =SUM(Q9:Q27) -> 2940000 | R28: Total | W28: =SUM(W9:W23) -> 700000 | X28: Total | AC28: =SUM(AC9:AC23) -> 0
C29: =1+C28 -> 3 | H29: =G29*E29 -> 0 | L29: Grantotal | Q29: =Q28+W28+AC28 -> 3640000
C30: =1+C29 -> 4 | H30: =G30*E30 -> 0
C31: =1+C30 -> 5 | H31: =G31*E31 -> 0
C32: =1+C31 -> 6 | H32: =G32*E32 -> 0
C33: =1+C32 -> 7 | H33: =G33*E33 -> 0
C34: =1+C33 -> 8 | H34: =G34*E34 -> 0 | L34: =7*3 -> 21
C35: =1+C34 -> 9 | H35: =G35*E35 -> 0 | L35: =L34*24 -> 504
C36: =1+C35 -> 10 | H36: =G36*E36 -> 0
C37: Total | H37: =SUM(H26:H36) -> 0 | I37: =H37 -> 0
C39: Keperluan Catering W3 Oktober 2026
C40: No | D40: Nama Barang/Jasa | E40: Qty | F40: Satuan | G40: Harga Satuan | H40: Total Harga
C42: 1 | D42: Catering Staff (7 Orang) | F42: pack | H42: =G42*E42 -> 0
C43: =1+C42 -> 2 | D43: Catering KHL (3 Orang) | F43: pack | H43: =G43*E43 -> 0
C44: =1+C43 -> 3 | H44: =G44*E44 -> 0
C45: =1+C44 -> 4 | H45: =G45*E45 -> 0
C46: =1+C45 -> 5 | H46: =G46*E46 -> 0
C47: =1+C46 -> 6 | H47: =G47*E47 -> 0
...

Sheet Perdin & Cuti
C2: PT ENERGI BATUBARA LESTARI RENCANA ANGGARAN BULANAN (RAB) Departemen HCGA
C7: Keperluan HCGS W1 Oktober 2026
C8: No | D8: Nama Barang/Jasa | E8: Qty | F8: Satuan | G8: Harga Satuan | H8: Total Harga
C10: 1 | D10: Lumpsum Cuti Periodik Karyawan | E10: 1 | F10: orang | H10: =G10*E10 -> 0
C11: =1+C10 -> 2 | D11: Perjalanan Dinas Karyawan | H11: =G11*E11 -> 0
C12: =1+C11 -> 3 | H12: =G12*E12 -> 0
C13: =1+C12 -> 4 | H13: =G13*E13 -> 0
C14: =1+C13 -> 5 | H14: =G14*E14 -> 0
C15: =1+C14 -> 6 | H15: =G15*E15 -> 0
C16: =1+C15 -> 7 | H16: =G16*E16 -> 0
C17: =1+C16 -> 8 | H17: =G17*E17 -> 0
C18: =1+C17 -> 9 | H18: =G18*E18 -> 0
C19: =1+C18 -> 10 | H19: =G19*E19 -> 0
C20: Total | H20: =SUM(H10:H19) -> 0 | I20: =H20 -> 0
C22: Keperluan HCGS W2 Oktober 2026
C23: No | D23: Nama Barang/Jasa | E23: Qty | F23: Satuan | G23: Harga Satuan | H23: Total Harga
C25: 1 | D25: Lumpsum Cuti Periodik Karyawan | E25: 1 | F25: orang | H25: =G25*E25 -> 0
C26: =1+C25 -> 2 | D26: Perjalanan Dinas Karyawan | H26: =G26*E26 -> 0
C27: =1+C26 -> 3 | H27: =G27*E27 -> 0
C28: =1+C27 -> 4 | H28: =G28*E28 -> 0
C29: =1+C28 -> 5 | H29: =G29*E29 -> 0
C30: =1+C29 -> 6 | H30: =G30*E30 -> 0
C31: =1+C30 -> 7 | H31: =G31*E31 -> 0
C32: =1+C31 -> 8 | H32: =G32*E32 -> 0
C33: =1+C32 -> 9 | H33: =G33*E33 -> 0
C34: =1+C33 -> 10 | H34: =G34*E34 -> 0
C35: Total | H35: =SUM(H25:H34) -> 0 | I35: =H35 -> 0
C37: Keperluan HCGS W3 Oktober 2026
C38: No | D38: Nama Barang/Jasa | E38: Qty | F38: Satuan | G38: Harga Satuan | H38: Total Harga
C40: 1 | D40: Biaya perjalanan dinas & Cuti | E40: 1 | F40: orang | H40: =G40*E40 -> 0
C41: =1+C40 -> 2 | H41: =G41*E41 -> 0
C42: =1+C41 -> 3 | H42: =G42*E42 -> 0
C43: =1+C42 -> 4 | H43: =G43*E43 -> 0
C44: =1+C43 -> 5 | H44: =G44*E44 -> 0
C45: =1+C44 -> 6 | H45: =G45*E45 -> 0
C46: =1+C45 -> 7 | H46: =G46*E46 -> 0
C47: =1+C46 -> 8 | H47: =G47*E47 -> 0
C48: =1+C47 -> 9 | H48: =G48*E48 -> 0
C49: =1+C48 -> 10 | H49: =G49*E49 -> 0
C50: Total | H50: =SUM(H40:H49) -> 0 | I50: =H50 -> 0
...

Sheet Listrik PLN
C2: PT ENERGI BATUBARA LESTARI RENCANA ANGGARAN BULANAN (RAB) Departemen HCGA
C7: Keperluan Listrik PLN W1 Oktober 2026
C8: No | D8: Nama Barang/Jasa | E8: Qty | F8: Satuan | G8: Harga Satuan | H8: Total Harga
C10: 1 | D10: Listrik Stockpile EBL | H10: =G10*E10 -> 0
C11: =1+C10 -> 2 | D11: Listrik Mess Kupang | H11: =G11*E11 -> 0
C12: =1+C11 -> 3 | D12: Listrik Gudang Handak EBL | H12: =G12*E12 -> 0
C13: =1+C12 -> 4 | D13: Listrik Office 42 | H13: =G13*E13 -> 0
C14: =1+C13 -> 5 | D14: Listrik Kantor & Mess EBL | H14: =G14*E14 -> 0
C15: Total | H15: =SUM(H10:H14) -> 0 | I15: =H15 -> 0
C17: Keperluan Listrik PLN W2 Oktober 2026
C18: No | D18: Nama Barang/Jasa | E18: Qty | F18: Satuan | G18: Harga Satuan | H18: Total Harga
C20: 1 | D20: Listrik Stockpile EBL | H20: =G20*E20 -> 0
C21: =1+C20 -> 2 | D21: Listrik Mess Kupang | H21: =G21*E21 -> 0
C22: =1+C21 -> 3 | D22: Listrik Gudang Handak EBL | H22: =G22*E22 -> 0
C23: =1+C22 -> 4 | D23: Listrik Office 42 | H23: =G23*E23 -> 0
C24: =1+C23 -> 5 | D24: Listrik Kantor & Mess EBL | H24: =G24*E24 -> 0
C25: Total | H25: =SUM(H20:H24) -> 0 | I25: =H25 -> 0
C27: Keperluan Listrik PLN W3 Oktober 2026
C28: No | D28: Nama Barang/Jasa | E28: Qty | F28: Satuan | G28: Harga Satuan | H28: Total Harga
C30: 1 | D30: Listrik Stockpile EBL | H30: =G30*E30 -> 0
C31: =1+C30 -> 2 | D31: Listrik Mess Kupang | H31: =G31*E31 -> 0
C32: =1+C31 -> 3 | D32: Listrik Gudang Handak EBL | H32: =G32*E32 -> 0
C33: =1+C32 -> 4 | D33: Listrik Office 42 | H33: =G33*E33 -> 0
C34: =1+C33 -> 5 | D34: Listrik Kantor & Mess EBL | H34: =G34*E34 -> 0
C35: Total | H35: =SUM(H30:H34) -> 0 | I35: =H35 -> 0
C37: Keperluan Listrik PLN W4 Oktober 2026
C38: No | D38: Nama Barang/Jasa | E38: Qty | F38: Satuan | G38: Harga Satuan | H38: Total Harga
C40: 1 | D40: Listrik Stockpile EBL | H40: =G40*E40 -> 0
C41: =1+C40 -> 2 | D41: Listrik Mess Kupang | H41: =G41*E41 -> 0
C42: =1+C41 -> 3 | D42: Listrik Gudang Handak EBL | H42: =G42*E42 -> 0
C43: =1+C42 -> 4 | D43: Listrik Office 42 | H43: =G43*E43 -> 0
C44: =1+C43 -> 5 | D44: Listrik Kantor & Mess EBL | H44: =G44*E44 -> 0
C45: Total | H45: =SUM(H40:H44) -> 0 | I45: =H45 -> 0
C49: Grand Total | H49: =SUM(I:I) -> 0

Sheet Air PDAM
C2: PT ENERGI BATUBARA LESTARI RENCANA ANGGARAN BULANAN (RAB) Departemen HCGA
C7: Keperluan Air PDAM PLN W1 Oktober 2026
C8: No | D8: Nama Barang/Jasa | E8: Qty | F8: Satuan | G8: Harga Satuan | H8: Total Harga
C10: 1 | D10: Air PDAM Stockpile EBL | H10: =G10*E10 -> 0
C11: =1+C10 -> 2 | D11: Air PDAM Mess Kupang | H11: =G11*E11 -> 0
C12: =1+C11 -> 3 | D12: Air PDAM Gudang Handak EBL | H12: =G12*E12 -> 0
C13: =1+C12 -> 4 | D13: Air PDAM Office 42 | H13: =G13*E13 -> 0
C14: =1+C13 -> 5 | D14: Air PDAM Kantor & Mess EBL | H14: =G14*E14 -> 0
C15: Total | H15: =SUM(H10:H14) -> 0 | I15: =H15 -> 0
C17: Keperluan Air PDAM PLN W2 Oktober 2026
C18: No | D18: Nama Barang/Jasa | E18: Qty | F18: Satuan | G18: Harga Satuan | H18: Total Harga
C20: 1 | D20: Air PDAM Stockpile EBL | H20: =G20*E20 -> 0
C21: =1+C20 -> 2 | D21: Air PDAM Mess Kupang | H21: =G21*E21 -> 0
C22: =1+C21 -> 3 | D22: Air PDAM Gudang Handak EBL | H22: =G22*E22 -> 0
C23: =1+C22 -> 4 | D23: Air PDAM Office 42 | H23: =G23*E23 -> 0
C24: =1+C23 -> 5 | D24: Air PDAM Kantor & Mess EBL | H24: =G24*E24 -> 0
C25: Total | H25: =SUM(H20:H24) -> 0 | I25: =H25 -> 0
C27: Keperluan Air PDAM PLN W3 Oktober 2026
C28: No | D28: Nama Barang/Jasa | E28: Qty | F28: Satuan | G28: Harga Satuan | H28: Total Harga
C30: 1 | D30: Air PDAM Stockpile EBL | H30: =G30*E30 -> 0
C31: =1+C30 -> 2 | D31: Air PDAM Mess Kupang | H31: =G31*E31 -> 0
C32: =1+C31 -> 3 | D32: Air PDAM Gudang Handak EBL | H32: =G32*E32 -> 0
C33: =1+C32 -> 4 | D33: Air PDAM Office 42 | H33: =G33*E33 -> 0
C34: =1+C33 -> 5 | D34: Air PDAM Kantor & Mess EBL | H34: =G34*E34 -> 0
C35: Total | H35: =SUM(H30:H34) -> 0 | I35: =H35 -> 0
C37: Keperluan Air PDAM PLN W4 Oktober 2026
C38: No | D38: Nama Barang/Jasa | E38: Qty | F38: Satuan | G38: Harga Satuan | H38: Total Harga
C40: 1 | D40: Air PDAM Stockpile EBL | H40: =G40*E40 -> 0
C41: =1+C40 -> 2 | D41: Air PDAM Mess Kupang | H41: =G41*E41 -> 0
C42: =1+C41 -> 3 | D42: Air PDAM Gudang Handak EBL | H42: =G42*E42 -> 0
C43: =1+C42 -> 4 | D43: Air PDAM Office 42 | H43: =G43*E43 -> 0
C44: =1+C43 -> 5 | D44: Air PDAM Kantor & Mess EBL | H44: =G44*E44 -> 0
C45: Total | H45: =SUM(H40:H44) -> 0 | I45: =H45 -> 0
C49: Grand Total | H49: =SUM(I:I) -> 0

Sheet Telp & Internet
C2: PT ENERGI BATUBARA LESTARI RENCANA ANGGARAN BULANAN (RAB) Departemen HCGA
C7: Keperluan Telp & Internet W1 Oktober 2026
C8: No | D8: Nama Barang/Jasa | E8: Qty | F8: Satuan | G8: Harga Satuan | H8: Total Harga
C10: 1 | D10: Pembayaran Indihome PT EBL ( Mess Kantor) | H10: =G10*E10 -> 0
C11: =1+C10 -> 2 | D11: Pembayaran Indihome PT EBL ( Mess Tahura) | H11: =G11*E11 -> 0
C12: =1+C11 -> 3 | D12: Pembayaran Telkom Speedy PT EBL (Kantor) | H12: =G12*E12 -> 0
C13: =1+C12 -> 4 | H13: =G13*E13 -> 0
C14: =1+C13 -> 5 | H14: =G14*E14 -> 0
C15: Total | H15: =SUM(H10:H14) -> 0 | I15: =H15 -> 0
C17: Keperluan Telp & Internet W2 Oktober 2026
C18: No | D18: Nama Barang/Jasa | E18: Qty | F18: Satuan | G18: Harga Satuan | H18: Total Harga
C20: 1 | H20: =G20*E20 -> 0
C21: =1+C20 -> 2 | H21: =G21*E21 -> 0
C22: =1+C21 -> 3 | H22: =G22*E22 -> 0
C23: =1+C22 -> 4 | H23: =G23*E23 -> 0
C24: =1+C23 -> 5 | H24: =G24*E24 -> 0
C25: Total | H25: =SUM(H20:H24) -> 0 | I25: =H25 -> 0
C27: Keperluan Telp & Internet W3 Oktober 2026
C28: No | D28: Nama Barang/Jasa | E28: Qty | F28: Satuan | G28: Harga Satuan | H28: Total Harga
C30: 1 | H30: =G30*E30 -> 0
C31: =1+C30 -> 2 | H31: =G31*E31 -> 0
C32: =1+C31 -> 3 | H32: =G32*E32 -> 0
C33: =1+C32 -> 4 | H33: =G33*E33 -> 0
C34: =1+C33 -> 5 | H34: =G34*E34 -> 0
C35: Total | H35: =SUM(H30:H34) -> 0 | I35: =H35 -> 0
C37: Keperluan Telp & Internet W4 Oktober 2026
C38: No | D38: Nama Barang/Jasa | E38: Qty | F38: Satuan | G38: Harga Satuan | H38: Total Harga
C40: 1 | H40: =G40*E40 -> 0
C41: =1+C40 -> 2 | H41: =G41*E41 -> 0
C42: =1+C41 -> 3 | H42: =G42*E42 -> 0
C43: =1+C42 -> 4 | H43: =G43*E43 -> 0
C44: =1+C43 -> 5 | H44: =G44*E44 -> 0
C45: Total | H45: =SUM(H40:H44) -> 0 | I45: =H45 -> 0
C49: Grand Total | H49: =SUM(I:I) -> 0

Sheet Pantry
C2: PT ENERGI BATUBARA LESTARI RENCANA ANGGARAN BULANAN (RAB) Departemen HCGA
C7: Keperluan Pantry W1 Oktober 2026
C8: No | D8: Nama Barang/Jasa | E8: Qty | F8: Satuan | G8: Harga Satuan | H8: Total Harga
C10: 1 | D10: Air Galon | F10: galon | H10: =G10*E10 -> 0
C11: 2 | D11: Gas LPG | F11: tabung | H11: =G11*E11 -> 0
C12: =1+C11 -> 3 | D12: Pembersih Kamar mandi | E12: 1 | F12: btl | H12: =G12*E12 -> 0
C13: =1+C12 -> 4 | D13: Tissue | E13: 1 | F13: pack | H13: =G13*E13 -> 0
C14: =1+C13 -> 5 | D14: Pengharum Ruangan | E14: 1 | F14: pcs | H14: =G14*E14 -> 0
C15: =1+C14 -> 6 | D15: Trashbag | E15: 2 | F15: pack | H15: =G15*E15 -> 0
C16: =1+C15 -> 7 | D16: Pembersih Lantai | E16: 2 | F16: pack | H16: =G16*E16 -> 0
C17: =1+C16 -> 8 | D17: Kamper Kamar mandi | E17: 2 | F17: bks | H17: =G17*E17 -> 0
C18: =1+C17 -> 9 | D18: Semprotan nyamuk | E18: 2 | F18: btl | H18: =G18*E18 -> 0
C19: =1+C18 -> 10 | D19: Obat nyamuk bakar | E19: 1 | F19: Bks | H19: =G19*E19 -> 0
C20: =1+C19 -> 11 | D20: Sabun cuci piring | E20: 2 | F20: pack | H20: =G20*E20 -> 0
C21: Total | H21: =SUM(H11:H20) -> 0 | I21: =H21 -> 0
C23: Keperluan Pantry W2 Oktober 2026
C24: No | D24: Nama Barang/Jasa | E24: Qty | F24: Satuan | G24: Harga Satuan | H24: Total Harga
C26: 1 | D26: Air Galon | F26: galon | H26: =G26*E26 -> 0
C27: 2 | D27: Gas LPG | F27: tabung | H27: =G27*E27 -> 0
C28: =1+C27 -> 3 | D28: Pembersih Kamar mandi | E28: 1 | F28: btl | H28: =G28*E28 -> 0
C29: =1+C28 -> 4 | D29: Tissue | E29: 1 | F29: pack | H29: =G29*E29 -> 0
C30: =1+C29 -> 5 | D30: Pengharum Ruangan | E30: 1 | F30: pcs | H30: =G30*E30 -> 0
C31: =1+C30 -> 6 | D31: Trashbag | E31: 2 | F31: pack | H31: =G31*E31 -> 0
C32: =1+C31 -> 7 | D32: Pembersih Lantai | E32: 2 | F32: pack | H32: =G32*E32 -> 0
C33: =1+C32 -> 8 | D33: Kamper Kamar mandi | E33: 2 | F33: bks | H33: =G33*E33 -> 0
C34: =1+C33 -> 9 | D34: Semprotan nyamuk | E34: 2 | F34: btl | H34: =G34*E34 -> 0
C35: =1+C34 -> 10 | D35: Obat nyamuk bakar | E35: 1 | F35: Bks | H35: =G35*E35 -> 0
C36: =1+C35 -> 11 | D36: Sabun cuci piring | E36: 2 | F36: pack | H36: =G36*E36 -> 0
C37: Total | H37: =SUM(H27:H36) -> 0 | I37: =H37 -> 0
C39: Keperluan Pantry W3 Oktober 2026
C40: No | D40: Nama Barang/Jasa | E40: Qty | F40: Satuan | G40: Harga Satuan | H40: Total Harga
C42: 1 | D42: Air Galon | F42: Galon | H42: =G42*E42 -> 0
C43: 2 | D43: Gas LPG | F43: tabung | H43: =G43*E43 -> 0
C44: =1+C43 -> 3 | D44: Pembersih Kamar mandi | E44: 1 | F44: btl | H44: =G44*E44 -> 0
C45: =1+C44 -> 4 | D45: Tissue | E45: 1 | F45: pack | H45: =G45*E45 -> 0
C46: =1+C45 -> 5 | D46: Pengharum Ruangan | E46: 1 | F46: pcs | H46: =G46*E46 -> 0
C47: =1+C46 -> 6 | D47: Trashbag | E47: 2 | F47: pack | H47: =G47*E47 -> 0
C48: =1+C47 -> 7 | D48: Pembersih Lantai | E48: 2 | F48: pack | H48: =G48*E48 -> 0
C49: =1+C48 -> 8 | D49: Kamper Kamar mandi | E49: 2 | F49: bks | H49: =G49*E49 -> 0
C50: =1+C49 -> 9 | D50: Semprotan nyamuk | E50: 2 | F50: btl | H50: =G50*E50 -> 0
...

Sheet KHL
C2: PT ENERGI BATUBARA LESTARI RENCANA ANGGARAN BULANAN (RAB) Departemen HCGA
C7: Keperluan KHL W1 Oktober 2026
C8: No | D8: Nama Barang/Jasa | E8: Qty | F8: Satuan | G8: Harga Satuan | H8: Total Harga
C10: 1 | H10: =G10*E10 -> 0
C11: =1+C10 -> 2 | H11: =G11*E11 -> 0
C12: =1+C11 -> 3 | H12: =G12*E12 -> 0
C13: =1+C12 -> 4 | H13: =G13*E13 -> 0
C14: =1+C13 -> 5 | H14: =G14*E14 -> 0
C15: =1+C14 -> 6 | H15: =G15*E15 -> 0
C16: =1+C15 -> 7 | H16: =G16*E16 -> 0
C17: =1+C16 -> 8 | H17: =G17*E17 -> 0
C18: =1+C17 -> 9 | H18: =G18*E18 -> 0
C19: =1+C18 -> 10 | H19: =G19*E19 -> 0
C20: Total | H20: =SUM(H10:H19) -> 0 | I20: =H20 -> 0
C22: Keperluan KHL W2 Oktober 2026
C23: No | D23: Nama Barang/Jasa | E23: Qty | F23: Satuan | G23: Harga Satuan | H23: Total Harga
C25: 1 | H25: =G25*E25 -> 0
C26: =1+C25 -> 2 | H26: =G26*E26 -> 0
C27: =1+C26 -> 3 | H27: =G27*E27 -> 0
C28: =1+C27 -> 4 | H28: =G28*E28 -> 0
C29: =1+C28 -> 5 | H29: =G29*E29 -> 0
C30: =1+C29 -> 6 | H30: =G30*E30 -> 0
C31: =1+C30 -> 7 | H31: =G31*E31 -> 0
C32: =1+C31 -> 8 | H32: =G32*E32 -> 0
C33: =1+C32 -> 9 | H33: =G33*E33 -> 0
C34: =1+C33 -> 10 | H34: =G34*E34 -> 0
C35: Total | H35: =SUM(H25:H34) -> 0 | I35: =H35 -> 0
C37: Keperluan KHL W3 Oktober 2026
C38: No | D38: Nama Barang/Jasa | E38: Qty | F38: Satuan | G38: Harga Satuan | H38: Total Harga
C40: 1 | H40: =G40*E40 -> 0
C41: =1+C40 -> 2 | H41: =G41*E41 -> 0
C42: =1+C41 -> 3 | H42: =G42*E42 -> 0
C43: =1+C42 -> 4 | H43: =G43*E43 -> 0
C44: =1+C43 -> 5 | H44: =G44*E44 -> 0
C45: =1+C44 -> 6 | H45: =G45*E45 -> 0
C46: =1+C45 -> 7 | H46: =G46*E46 -> 0
C47: =1+C46 -> 8 | H47: =G47*E47 -> 0
C48: =1+C47 -> 9 | H48: =G48*E48 -> 0
C49: =1+C48 -> 10 | H49: =G49*E49 -> 0
C50: Total | H50: =SUM(H40:H49) -> 0 | I50: =H50 -> 0
...
